Workbook
Name Slicer_City: #N/A
Name Slicer_Department: #N/A

Sheet Old_Patient_Records
A1: Patient_ID | B1: Patient_Name | C1: Age | D1: Gender | E1: City | F1: Blood_Group | G1: Diagnosis | H1: Height_cm | I1: Weight_kg | J1: Smoking_Status | K1: Has_Insurance | L1: Department | M1: Admission_Date | N1: Bill_Amount
A2: PT-1424 | B2: Valentina Perez | C2: 200 | D2: Male | E2: Delhi | F2: Ab- | G2: Obesity | H2: 164 | I2: 125.7 | J2: Former | K2: TRUE | L2: cardiology | M2: 2023-02-04 | N2: 17228.95
A3: PT-1017 | B3: Juan Reddy | C3: 200 | D3: Female | E3: Hyderabad | F3: Ab- | G3: Covid19 | H3: 170 | I3: 99.4 | J3: N | K3: Y | L3: Psychiatry | M3: 05-23-2021 | N3: 17881.73
A4: PT-1507 | B4: Yuki Patel | C4: 150 | D4: Male | E4: Sydney | F4: O+ | G4: Unknown | H4: 167.9 | I4: 70.7 | J4: Never | L4: Nephrology | M4: 2021-04-27 | N4: 27888.06
A5: PT-1305 | B5: Wei Nair | C5: 150 | D5: Male | E5: Mumbai | F5: B- | G5: Unknown | H5: 155.9 | I5: 72 | J5: yes | L5: Orthopedics | M5: 12-14-2022 | N5: 8447.59
A6: PT-1124 | B6: Pari Anderson | C6: 150 | D6: Female | E6: Bengaluru | F6: Ab- | G6: Diabetes Type 2 | H6: 147.4 | I6: 106.4 | K6: 0 | L6: Dermatology | M6: 27/05/2023 | N6: 30999.48
A7: PT-1277 | B7: David Hernandez | C7: 95 | D7: Female | E7: Chennai | F7: A- | G7: Anemia | H7: 175.4 | I7: 61.5 | J7: No | K7: 1 | L7: Dermatology | M7: 23-Sep-2022 | N7: 26930.03
A8: PT-1295 | B8: Ishaan Ibrahim | C8: 95 | D8: Other | E8: Houston | F8: O+ | G8: Hypothyroidism | H8: 178 | I8: 108 | J8: Unknown | L8: Nephrology | M8: 06-25-2023 | N8: 34612.78
A9: PT-1136 | B9: Reyansh Sanchez | C9: 95 | D9: Other | E9: Mumbai | F9: A- | G9: Diabetes Type 2 | H9: 166.6 | I9: 123 | J9: Yes | K9: 1 | L9: Endocrinology | M9: 09/05/2023 | N9: 16429.2
A10: PT-1087 | B10: Noor Chen | C10: 95 | D10: Female | E10: Jaipur | F10: O+ | G10: Chronic Kidney Disease | H10: 160 | I10: 41.5 | K10: No | L10: Oncology | M10: 23.09.2022 | N10: 43668.91
A11: PT-1455 | B11: Ana Gupta | C11: 95 | D11: Male | E11: Pune | F11: A+ | G11: Hypertension | H11: 160 | I11: 117 | J11: Never | K11: FALSE | L11: Dermatology | M11: 07-11-2021 | N11: 23560.94
A12: PT-1394 | B12: Maria Wilson | C12: 94 | D12: Female | E12: Mumbai | F12: Ab- | G12: Anemia | H12: 156 | I12: 103 | J12: Unknown | K12: TRUE | L12: General Medicine | M12: 21/10/2022
A13: PT-1029 | B13: Carlos Ibrahim | C13: 94 | D13: Other | E13: Mumbai | F13: A+ | G13: Thyroid Disorder | H13: 181 | I13: 114.3 | J13: N | K13: no | L13: Psychiatry | M13: 06-27-2021 | N13: 44140.74
A14: PT-1528 | B14: Sai Kumar | C14: 94 | D14: Male | E14: Mumbai | F14: A+ | G14: Allergy | H14: 157 | I14: 92.9 | J14: no | K14: 0 | L14: Psychiatry | M14: 10-02-2022 | N14: 21545.06
A15: PT-1459 | B15: Omar Flores | C15: 94 | D15: Female | E15: Hyderabad | F15: O+ | G15: Diabetes Type 2 | H15: 193.2 | I15: 68.5 | J15: Y | K15: 1 | L15: Gastroenterology | M15: 08-Jan-2021 | N15: 47194.53
A16: PT-1335 | B16: Ming Mehta | C16: 93 | D16: Female | E16: Hyderabad | F16: Unknown | G16: Heart Disease | H16: 150.1 | I16: 82 | J16: N | K16: no | L16: Oncology | M16: 06/05/2023 | N16: 22214.7
A17: PT-1051 | B17: Hiroshi Reddy | C17: 93 | D17: Male | E17: Ahmedabad | F17: Ab+ | G17: Hypertension | H17: 152 | I17: 124 | J17: Unknown | L17: Cardiology | M17: 2021-09-03 | N17: 42893.82
A18: PT-1451 | B18: Mary Gonzalez | C18: 93 | D18: Female | E18: Chennai | F18: B- | G18: Covid19 | H18: 176 | I18: 110 | J18: Unknown | K18: TRUE | L18: Pediatrics | M18: 03-18-2021 | N18: 8480.54
A19: PT-1095 | B19: Barbara Davis | C19: 93 | D19: Other | E19: Mumbai | F19: A+ | G19: Hypothyroidism | H19: 184 | I19: 54.4 | K19: No | L19: Dermatology | M19: 08-28-2022 | N19: 30923.96
A20: PT-1043 | B20: Ana Rodriguez | C20: 92 | D20: Male | E20: Los Angeles | F20: A- | G20: Thyroid Disorder | H20: 146.6 | I20: 107.2 | J20: No | L20: Gastroenterology | M20: 25-Jul-2021 | N20: -8735.06
A21: PT-1481 | B21: Davis Reyansh | C21: 92 | D21: Male | E21: Bengaluru | F21: Ab+ | G21: Diabetes | H21: 191.2 | I21: 55 | J21: N | L21: Orthopedics | M21: 13.08.2022 | N21: 653.79
A22: PT-1470 | B22: Diya Miller | C22: 92 | D22: Male | E22: Bengaluru | F22: B- | G22: Anxiety | H22: 177.1 | I22: 125.8 | J22: Never | K22: FALSE | L22: Oncology | M22: 07-11-2022 | N22: 31334.09
A23: PT-1242 | B23: Wei Iyer | C23: 92 | D23: Male | E23: Delhi | F23: O- | G23: Diabetes Type 2 | H23: 146 | I23: 43 | J23: Y | K23: TRUE | L23: Neurology | M23: 20/02/2022 | N23: 3773.75
A24: PT-1540 | B24: Carlos Patel | C24: 92 | D24: Female | E24: Sydney | F24: Ab- | G24: Chronic Kidney Disease | H24: 147 | J24: Yes | K24: 0 | L24: Nephrology | M24: 10.11.2021 | N24: 36941.71
A25: PT-1116 | B25: Anderson Krishna | C25: 92 | D25: Male | E25: Bengaluru | F25: B+ | G25: Tuberculosis | H25: 156.8 | I25: 123.1 | J25: Current | K25: Yes | L25: Endocrinology | M25: 07.01.2023 | N25: 44827.33
A26: PT-1035 | B26: Layla Lopez | C26: 91 | D26: Male | E26: Chennai | F26: Ab- | G26: Asthma | H26: 187.9 | I26: 89 | J26: Y | K26: yes | L26: Cardiology | M26: 03/05/2021 | N26: 39735.11
A27: PT-1357 | B27: Vivaan Davis | C27: 91 | D27: Female | E27: Toronto | F27: Ab- | G27: Asthma | H27: 174 | I27: 84 | J27: N | K27: TRUE | L27: cardiology | M27: 2023-04-30 | N27: 43052.6
A28: PT-1120 | B28: Robert Sharma | C28: 91 | D28: Male | E28: Bengaluru | F28: B- | G28: Unknown | H28: 194.6 | I28: 50.3 | J28: Current | L28: orthopedics | M28: 2023/03/07 | N28: 19930.93
A29: PT-1399 | B29: Wei Gupta | C29: 91 | D29: Male | E29: Mumbai | F29: O+ | G29: Migraine | H29: 175.4 | I29: 94 | J29: Yes | K29: No | L29: Endocrinology | M29: 09.07.2021 | N29: 35724.67
A30: PT-1386 | B30: Carlos Rodriguez | C30: 90 | D30: Female | E30: Hyderabad | F30: Ab+ | G30: Chronic Kidney Disease | H30: 155 | I30: 47 | J30: Current | K30: N | L30: Oncology | M30: 13/07/2023 | N30: 13011.95
A31: PT-1027 | B31: Jose Nair | C31: 90 | D31: Male | E31: Pune | F31: O+ | G31: Obesity | H31: 191 | I31: 54.7 | J31: No | K31: 0 | L31: Cardiology | M31: 2022/10/01 | N31: 34028.69
A32: PT-1322 | B32: Pari Miller | C32: 90 | D32: Female | E32: Delhi | F32: B- | G32: Depression | H32: 180 | J32: Never | K32: Y | L32: Orthopedics | M32: 04/07/2021 | N32: 15222.43
A33: PT-1201 | B33: Robert Zhang | C33: 90 | D33: Other | E33: Bengaluru | F33: Unknown | G33: Hypertension | H33: 175 | I33: 118.9 | J33: Y | K33: no | L33: Cardiology | M33: 2021/01/15 | N33: 26365.76
A34: PT-1022 | B34: Camila Reddy | C34: 90 | D34: Other | E34: Chicago | F34: A- | G34: Depression | H34: 172 | I34: 81.8 | J34: Former | K34: 0 | L34: Psychiatry | M34: 31-Oct-2023 | N34: 41613.17
A35: PT-1505 | B35: Maria Garcia | C35: 90 | D35: Other | E35: Houston | F35: B- | G35: Hypertension | H35: 195 | I35: 58 | J35: Current | K35: no | L35: Orthopedics | M35: 2022-03-08 | N35: 18933.3
A36: PT-1290 | B36: Ayaan Lopez | C36: 90 | D36: Female | E36: Pune | F36: Ab- | G36: Covid19 | H36: 180 | I36: 45.7 | J36: Former | K36: FALSE | L36: General Medicine | M36: 2023-12-15 | N36: 23773.11
A37: PT-1321 | B37: Myra Ramirez | C37: 90 | D37: Female | E37: Mumbai | F37: Unknown | G37: Chronic Kidney Disease | H37: 157 | I37: 104.4 | J37: Yes | L37: Nephrology | M37: 13.03.2021 | N37: 33280.06
A38: PT-1031 | B38: Barbara Verma | C38: 89 | D38: Female | E38: Jaipur | F38: O+ | G38: Chronic Kidney Disease | H38: 175 | I38: 80.8 | J38: Y | K38: no | L38: Cardiology | M38: 01-30-2022 | N38: 6417.96
A39: PT-1031 | B39: Barbara Verma | C39: 89 | D39: Female | E39: Jaipur | F39: O+ | G39: Chronic Kidney Disease | H39: 182 | I39: 80.8 | J39: Y | K39: no | L39: Cardiology | M39: 01-30-2022 | N39: 6417.96
A40: PT-1061 | B40: John Smith | C40: 89 | D40: Female | E40: Bengaluru | F40: Unknown | G40: Diabetes Type 2 | H40: 175 | I40: 75.6 | K40: N | L40: Neurology | M40: 14/11/2022 | N40: 4280.78
...

Sheet Updated_Records
A1: Patient_ID | B1: Patient_Name | C1: Age | D1: Gender | E1: City | F1: Blood_Group | G1: Diagnosis | H1: Height_cm | I1: Weight_kg | J1: Smoking_Status | K1: Has_Insurance | L1: Department | M1: Admission_Date | N1: Year | O1: Column1 | P1: Bill_Amount2 | Q1: Bill_Amount rank | R1: Age_Group | S1: BMI | T1: BMII | U1: Doctor_refrnece
A2: PT-1001 | B2: Davis Vivaan | C2: 14 | D2: Male | E2: Hyderabad | F2: B+ | G2: Anxiety | H2: 156.7 | I2: 94 | J2: Unknown | K2: Unknown | L2: Gastroenterology | M2: 45056 | N2: =Table1_3[[#This Row],[Admission_Date]] -> 45056 | O2: =Table1_3[[#This Row],[Admission_Date]] -> 45056 | P2: 22735.85 | Q2: =SUMPRODUCT(($L$2:$L$5000=L2)*($O$2:$O$5000>P2))+1 -> 42 | R2: Child | S2: 38.281581 | T2: Obese | U2: =INDEX(Table2[Doctor_Name],MATCH(Table1_3[[#This Row],[Department]],Table2[Department],0)) -> Dr. Sunita Sanchez
A3: PT-1002 | B3: Saanvi Ali | C3: 44 | D3: Female | E3: Bengaluru | F3: Ab+ | G3: Diabetes | H3: 158 | I3: 106 | J3: No | K3: No | L3: General Medicine | M3: 44797 | N3: =Table1_3[[#This Row],[Admission_Date]] -> 44797 | O3: =Table1_3[[#This Row],[Admission_Date]] -> 44797 | P3: 31116.73 | Q3: =SUMPRODUCT(($L$2:$L$5000=L3)*($O$2:$O$5000>P3))+1 -> 38 | R3: Adult | S3: 42.461144 | T3: Obese | U3: =INDEX(Table2[Doctor_Name],MATCH(Table1_3[[#This Row],[Department]],Table2[Department],0)) -> Dr. Arvind Wilson
A4: PT-1003 | B4: Aditya Jones | C4: 30 | D4: Female | E4: Bengaluru | F4: Ab+ | G4: Migraine | H4: 186.5 | I4: 58.9 | J4: Unknown | K4: Unknown | L4: Dermatology | M4: 44343 | N4: =Table1_3[[#This Row],[Admission_Date]] -> 44343 | O4: =Table1_3[[#This Row],[Admission_Date]] -> 44343 | P4: 31931.43 | Q4: =SUMPRODUCT(($L$2:$L$5000=L4)*($O$2:$O$5000>P4))+1 -> 35 | R4: Adult | S4: 16.933925 | T4: Underweight | U4: =INDEX(Table2[Doctor_Name],MATCH(Table1_3[[#This Row],[Department]],Table2[Department],0)) -> Dr. Neha Liu
A5: PT-1004 | B5: Martinez Sara | C5: 8 | D5: Female | E5: Delhi | F5: O+ | G5: Covid19 | H5: 155.5 | I5: 84.9 | J5: Yes | K5: Yes | L5: Cardiology | M5: 44702 | N5: =Table1_3[[#This Row],[Admission_Date]] -> 44702 | O5: =Table1_3[[#This Row],[Admission_Date]] -> 44702 | P5: 28287.72 | Q5: =SUMPRODUCT(($L$2:$L$5000=L5)*($O$2:$O$5000>P5))+1 -> 107 | R5: Child | S5: 35.1113 | T5: Obese | U5: =INDEX(Table2[Doctor_Name],MATCH(Table1_3[[#This Row],[Department]],Table2[Department],0)) -> Dr. Vikram Wang
A6: PT-1005 | B6: Liu Mary | C6: 66 | D6: Female | E6: Bengaluru | F6: A- | G6: Diabetes Type 2 | H6: 160.9 | I6: 74.6 | J6: Yes | K6: Yes | L6: General Medicine | M6: 44220 | N6: =Table1_3[[#This Row],[Admission_Date]] -> 44220 | O6: =Table1_3[[#This Row],[Admission_Date]] -> 44220 | P6: 36175.73 | Q6: =SUMPRODUCT(($L$2:$L$5000=L6)*($O$2:$O$5000>P6))+1 -> 38 | R6: Senior | S6: 28.815538 | T6: Overweight | U6: =INDEX(Table2[Doctor_Name],MATCH(Table1_3[[#This Row],[Department]],Table2[Department],0)) -> Dr. Arvind Wilson
A7: PT-1006 | B7: Maria Wang | C7: 59 | D7: Male | E7: Hyderabad | F7: A+ | G7: Chronic Kidney Disease | H7: 183 | I7: 67 | J7: Yes | K7: No | L7: Endocrinology | M7: 44527 | N7: =Table1_3[[#This Row],[Admission_Date]] -> 44527 | O7: =Table1_3[[#This Row],[Admission_Date]] -> 44527 | P7: 47698.24 | Q7: =SUMPRODUCT(($L$2:$L$5000=L7)*($O$2:$O$5000>P7))+1 -> 1 | R7: Adult | S7: 20.006569 | T7: Normal | U7: =INDEX(Table2[Doctor_Name],MATCH(Table1_3[[#This Row],[Department]],Table2[Department],0)) -> Dr. Rahul Nair
A8: PT-1007 | B8: Li Verma | C8: 40 | D8: Female | E8: Delhi | F8: Ab- | G8: Anxiety | H8: 152.9 | I8: 128 | J8: Yes | K8: Unknown | L8: Pediatrics | M8: 44328 | N8: =Table1_3[[#This Row],[Admission_Date]] -> 44328 | O8: =Table1_3[[#This Row],[Admission_Date]] -> 44328 | P8: 26619.85 | Q8: =SUMPRODUCT(($L$2:$L$5000=L8)*($O$2:$O$5000>P8))+1 -> 37 | R8: Adult | S8: 54.751371 | T8: Obese | U8: =INDEX(Table2[Doctor_Name],MATCH(Table1_3[[#This Row],[Department]],Table2[Department],0)) -> Dr. Arvind Chen
A9: PT-1008 | B9: Mateo Williams | C9: 86 | D9: Male | E9: Delhi | F9: Ab- | G9: Chronic Kidney Disease | H9: 165 | I9: 93 | J9: Unknown | K9: No | L9: Cardiology | M9: 44342 | N9: =Table1_3[[#This Row],[Admission_Date]] -> 44342 | O9: =Table1_3[[#This Row],[Admission_Date]] -> 44342 | P9: 31739.6 | Q9: =SUMPRODUCT(($L$2:$L$5000=L9)*($O$2:$O$5000>P9))+1 -> 107 | R9: Senior | S9: 34.15978 | T9: Obese | U9: =INDEX(Table2[Doctor_Name],MATCH(Table1_3[[#This Row],[Department]],Table2[Department],0)) -> Dr. Vikram Wang
A10: PT-1009 | B10: Gonzalez Arjun | C10: 28 | D10: Other | E10: Chennai | F10: Unknown | G10: Heart Disease | H10: 161 | I10: 99.3 | J10: No | K10: Yes | L10: Pediatrics | M10: 44307 | N10: =Table1_3[[#This Row],[Admission_Date]] -> 44307 | O10: =Table1_3[[#This Row],[Admission_Date]] -> 44307 | P10: 32846.05 | Q10: =SUMPRODUCT(($L$2:$L$5000=L10)*($O$2:$O$5000>P10))+1 -> 37 | R10: Adult | S10: 38.308707 | T10: Obese | U10: =INDEX(Table2[Doctor_Name],MATCH(Table1_3[[#This Row],[Department]],Table2[Department],0)) -> Dr. Arvind Chen
A11: PT-1010 | B11: Reyansh Garcia | C11: 18 | D11: Male | E11: Kolkata | F11: A+ | G11: Tuberculosis | H11: 149.3 | I11: 117 | J11: Yes | K11: Unknown | L11: General Medicine | M11: 44227 | N11: =Table1_3[[#This Row],[Admission_Date]] -> 44227 | O11: =Table1_3[[#This Row],[Admission_Date]] -> 44227 | P11: 46355.17 | Q11: =SUMPRODUCT(($L$2:$L$5000=L11)*($O$2:$O$5000>P11))+1 -> 1 | R11: Child | S11: 52.488752 | T11: Obese | U11: =INDEX(Table2[Doctor_Name],MATCH(Table1_3[[#This Row],[Department]],Table2[Department],0)) -> Dr. Arvind Wilson
A12: PT-1011 | B12: Aadhya Suzuki | C12: 1 | D12: Male | E12: Ahmedabad | F12: Ab- | G12: Arthritis | H12: 165 | I12: 67 | J12: Unknown | K12: Unknown | L12: General Medicine | M12: 44321 | N12: =Table1_3[[#This Row],[Admission_Date]] -> 44321 | O12: =Table1_3[[#This Row],[Admission_Date]] -> 44321 | P12: 16023.44 | Q12: =SUMPRODUCT(($L$2:$L$5000=L12)*($O$2:$O$5000>P12))+1 -> 38 | R12: Child | S12: 24.609734 | T12: Normal | U12: =INDEX(Table2[Doctor_Name],MATCH(Table1_3[[#This Row],[Department]],Table2[Department],0)) -> Dr. Arvind Wilson
A13: PT-1012 | B13: Hiroshi Smith | C13: 24 | D13: Female | E13: Sydney | F13: B+ | G13: Pneumonia | H13: 177 | I13: 44 | J13: No | K13: Unknown | L13: Ent | M13: 45119 | N13: =Table1_3[[#This Row],[Admission_Date]] -> 45119 | O13: =Table1_3[[#This Row],[Admission_Date]] -> 45119 | P13: 46767.96 | Q13: =SUMPRODUCT(($L$2:$L$5000=L13)*($O$2:$O$5000>P13))+1 -> 1 | R13: Young Adult | S13: 14.044496 | T13: Underweight | U13: =INDEX(Table2[Doctor_Name],MATCH(Table1_3[[#This Row],[Department]],Table2[Department],0)) -> Dr. Sunita Zhang
... A17: PT-1016 | B17: Zhang Aditya | C17: 14 | D17: Female | E17: Pune | F17: Unknown | G17: Thyroid Disorder | H17: 170 | I17: 128 | J17: No | K17: Yes | L17: Cardiology | M17: 44906 | N17: =Table1_3[[#This Row],[Admission_Date]] -> 44906 | O17: =Table1_3[[#This Row],[Admission_Date]] -> 44906 | P17: 40210.64 | Q17: =SUMPRODUCT(($L$2:$L$5000=L17)*($O$2:$O$5000>P17))+1 -> 107 | R17: Child | S17: 44.290657 | T17: Obese | U17: =INDEX(Table2[Doctor_Name],MATCH(Table1_3[[#This Row],[Department]],Table2[Department],0)) -> Dr. Vikram Wang
A18: PT-1017 | B18: Juan Reddy | C18: Invalid | D18: Female | E18: Hyderabad | F18: Ab- | G18: Covid19 | H18: 170 | I18: 99.4 | J18: No | K18: Yes | L18: Psychiatry | M18: 44339 | N18: =Table1_3[[#This Row],[Admission_Date]] -> 44339 | O18: =Table1_3[[#This Row],[Admission_Date]] -> 44339 | P18: 17881.73 | Q18: =SUMPRODUCT(($L$2:$L$5000=L18)*($O$2:$O$5000>P18))+1 -> 34 | R18: Unknown | S18: 34.394464 | T18: Obese | U18: =INDEX(Table2[Doctor_Name],MATCH(Table1_3[[#This Row],[Department]],Table2[Department],0)) -> Dr. Vikram Torres
A19: PT-1018 | B19: Michael Verma | C19: 23 | D19: Other | E19: Ahmedabad | F19: A- | G19: Diabetes | H19: 162.3 | I19: 129 | J19: No | K19: No | L19: Neurology | M19: 44718 | N19: =Table1_3[[#This Row],[Admission_Date]] -> 44718 | O19: =Table1_3[[#This Row],[Admission_Date]] -> 44718 | P19: 0 | Q19: =SUMPRODUCT(($L$2:$L$5000=L19)*($O$2:$O$5000>P19))+1 -> 35 | R19: Young Adult | S19: 48.972545 | T19: Obese | U19: =INDEX(Table2[Doctor_Name],MATCH(Table1_3[[#This Row],[Department]],Table2[Department],0)) -> Dr. Vikram Khan
A20: PT-1019 | B20: Diego Williams | C20: 86 | D20: Female | E20: Sydney | F20: O+ | G20: Pneumonia | H20: 158.4 | I20: 100 | J20: No | K20: Unknown | L20: Orthopedics | M20: 44457 | N20: =Table1_3[[#This Row],[Admission_Date]] -> 44457 | O20: =Table1_3[[#This Row],[Admission_Date]] -> 44457 | P20: 21312.09 | Q20: =SUMPRODUCT(($L$2:$L$5000=L20)*($O$2:$O$5000>P20))+1 -> 83 | R20: Senior | S20: 39.855627 | T20: Obese | U20: =INDEX(Table2[Doctor_Name],MATCH(Table1_3[[#This Row],[Department]],Table2[Department],0)) -> Dr. Anita Sanchez
A21: PT-1020 | B21: Noor Sanchez | C21: 1 | D21: Male | E21: Jaipur | F21: Ab+ | G21: Tuberculosis | H21: 157 | I21: 80 | J21: Yes | K21: No | L21: Endocrinology | M21: 44544 | N21: =Table1_3[[#This Row],[Admission_Date]] -> 44544 | O21: =Table1_3[[#This Row],[Admission_Date]] -> 44544 | P21: 4697.38 | Q21: =SUMPRODUCT(($L$2:$L$5000=L21)*($O$2:$O$5000>P21))+1 -> 45 | R21: Child | S21: 32.455678 | T21: Obese | U21: =INDEX(Table2[Doctor_Name],MATCH(Table1_3[[#This Row],[Department]],Table2[Department],0)) -> Dr. Rahul Nair
A22: PT-1021 | B22: Mateo Garcia | C22: 26 | D22: Male | E22: Mumbai | F22: A- | G22: Heart Disease | H22: 193.4 | I22: 120 | J22: Unknown | K22: Unknown | L22: Oncology | M22: 45209 | N22: =Table1_3[[#This Row],[Admission_Date]] -> 45209 | O22: =Table1_3[[#This Row],[Admission_Date]] -> 45209 | P22: 12577.23 | Q22: =SUMPRODUCT(($L$2:$L$5000=L22)*($O$2:$O$5000>P22))+1 -> 31 | R22: Adult | S22: 32.082508 | T22: Obese | U22: =INDEX(Table2[Doctor_Name],MATCH(Table1_3[[#This Row],[Department]],Table2[Department],0)) -> Dr. Suresh Johnson
A23: PT-1022 | B23: Camila Reddy | C23: 90 | D23: Other | E23: Chicago | F23: A- | G23: Depression | H23: 172 | I23: 81.8 | J23: No | K23: No | L23: Psychiatry | M23: 45230 | N23: =Table1_3[[#This Row],[Admission_Date]] -> 45230 | O23: =Table1_3[[#This Row],[Admission_Date]] -> 45230 | P23: 41613.17 | Q23: =SUMPRODUCT(($L$2:$L$5000=L23)*($O$2:$O$5000>P23))+1 -> 34 | R23: Senior | S23: 27.650081 | T23: Overweight | U23: =INDEX(Table2[Doctor_Name],MATCH(Table1_3[[#This Row],[Department]],Table2[Department],0)) -> Dr. Vikram Torres
A24: PT-1023 | B24: Wei Hussain | C24: 82 | D24: Male | E24: Pune | F24: Unknown | G24: Hypothyroidism | H24: 173.3 | I24: 70 | J24: Yes | K24: Yes | L24: Neurology | M24: 44981 | N24: =Table1_3[[#This Row],[Admission_Date]] -> 44981 | O24: =Table1_3[[#This Row],[Admission_Date]] -> 44981 | P24: 8063.86 | Q24: =SUMPRODUCT(($L$2:$L$5000=L24)*($O$2:$O$5000>P24))+1 -> 35 | R24: Senior | S24: 23.30778 | T24: Normal | U24: =INDEX(Table2[Doctor_Name],MATCH(Table1_3[[#This Row],[Department]],Table2[Department],0)) -> Dr. Vikram Khan
A25: PT-1024 | B25: Susan Khan | C25: 50 | D25: Male | E25: Toronto | F25: A+ | G25: Diabetes Type 2 | H25: 175.5 | I25: Invalid | J25: No | K25: Yes | L25: Endocrinology | M25: 45202 | N25: =Table1_3[[#This Row],[Admission_Date]] -> 45202 | O25: =Table1_3[[#This Row],[Admission_Date]] -> 45202 | P25: 27141.92 | Q25: =SUMPRODUCT(($L$2:$L$5000=L25)*($O$2:$O$5000>P25))+1 -> 45 | R25: Adult | S25: Unknown | T25: Unknown | U25: =INDEX(Table2[Doctor_Name],MATCH(Table1_3[[#This Row],[Department]],Table2[Department],0)) -> Dr. Rahul Nair
A26: PT-1025 | B26: Li Jones | C26: 50 | D26: Female | E26: Delhi | F26: Ab+ | G26: Allergy | H26: 166 | I26: 88.1 | J26: Unknown | K26: No | L26: Dermatology | M26: 44252 | N26: =Table1_3[[#This Row],[Admission_Date]] -> 44252 | O26: =Table1_3[[#This Row],[Admission_Date]] -> 44252 | P26: 32316.11 | Q26: =SUMPRODUCT(($L$2:$L$5000=L26)*($O$2:$O$5000>P26))+1 -> 35 | R26: Adult | S26: 31.971259 | T26: Obese | U26: =INDEX(Table2[Doctor_Name],MATCH(Table1_3[[#This Row],[Department]],Table2[Department],0)) -> Dr. Neha Liu
A27: PT-1026 | B27: Chen Robert | C27: 49 | D27: Male | E27: Pune | F27: Unknown | G27: Migraine | H27: 185 | I27: 71 | J27: Unknown | K27: Yes | L27: Endocrinology | M27: 44260 | N27: =Table1_3[[#This Row],[Admission_Date]] -> 44260 | O27: =Table1_3[[#This Row],[Admission_Date]] -> 44260 | P27: 0 | Q27: =SUMPRODUCT(($L$2:$L$5000=L27)*($O$2:$O$5000>P27))+1 -> 45 | R27: Adult | S27: 20.745069 | T27: Normal | U27: =INDEX(Table2[Doctor_Name],MATCH(Table1_3[[#This Row],[Department]],Table2[Department],0)) -> Dr. Rahul Nair
A28: PT-1027 | B28: Jose Nair | C28: 90 | D28: Male | E28: Pune | F28: O+ | G28: Obesity | H28: 191 | I28: 54.7 | J28: No | K28: No | L28: Cardiology | M28: 44571 | N28: =Table1_3[[#This Row],[Admission_Date]] -> 44571 | O28: =Table1_3[[#This Row],[Admission_Date]] -> 44571 | P28: 34028.69 | Q28: =SUMPRODUCT(($L$2:$L$5000=L28)*($O$2:$O$5000>P28))+1 -> 107 | R28: Senior | S28: 14.994107 | T28: Underweight | U28: =INDEX(Table2[Doctor_Name],MATCH(Table1_3[[#This Row],[Department]],Table2[Department],0)) -> Dr. Vikram Wang
A29: PT-1028 | B29: Arjun Ramirez | C29: 14 | D29: Female | E29: Pune | F29: B+ | G29: Diabetes Type 2 | H29: 152 | I29: 78.6 | J29: No | K29: Yes | L29: Dermatology | M29: 44895 | N29: =Table1_3[[#This Row],[Admission_Date]] -> 44895 | O29: =Table1_3[[#This Row],[Admission_Date]] -> 44895 | P29: 42553.99 | Q29: =SUMPRODUCT(($L$2:$L$5000=L29)*($O$2:$O$5000>P29))+1 -> 35 | R29: Child | S29: 34.020083 | T29: Obese | U29: =INDEX(Table2[Doctor_Name],MATCH(Table1_3[[#This Row],[Department]],Table2[Department],0)) -> Dr. Neha Liu
A30: PT-1029 | B30: Carlos Ibrahim | C30: 94 | D30: Other | E30: Mumbai | F30: A+ | G30: Thyroid Disorder | H30: 181 | I30: 114.3 | J30: No | K30: No | L30: Psychiatry | M30: 44374 | N30: =Table1_3[[#This Row],[Admission_Date]] -> 44374 | O30: =Table1_3[[#This Row],[Admission_Date]] -> 44374 | P30: 44140.74 | Q30: =SUMPRODUCT(($L$2:$L$5000=L30)*($O$2:$O$5000>P30))+1 -> 34 | R30: Senior | S30: 34.889045 | T30: Obese | U30: =INDEX(Table2[Doctor_Name],MATCH(Table1_3[[#This Row],[Department]],Table2[Department],0)) -> Dr. Vikram Torres
A31: PT-1030 | B31: Robert Wang | C31: 24 | D31: Female | E31: Hyderabad | F31: O+ | G31: Unknown | H31: 194.9 | I31: 86 | J31: No | K31: No | L31: Gastroenterology | M31: 45029 | N31: =Table1_3[[#This Row],[Admission_Date]] -> 45029 | O31: =Table1_3[[#This Row],[Admission_Date]] -> 45029 | P31: 27981.22 | Q31: =SUMPRODUCT(($L$2:$L$5000=L31)*($O$2:$O$5000>P31))+1 -> 42 | R31: Young Adult | S31: 22.639914 | T31: Normal | U31: =INDEX(Table2[Doctor_Name],MATCH(Table1_3[[#This Row],[Department]],Table2[Department],0)) -> Dr. Sunita Sanchez
A32: PT-1031 | B32: Barbara Verma | C32: 89 | D32: Female | E32: Jaipur | F32: O+ | G32: Chronic Kidney Disease | H32: 175 | I32: 80.8 | J32: Yes | K32: No | L32: Cardiology | M32: 44591 | N32: =Table1_3[[#This Row],[Admission_Date]] -> 44591 | O32: =Table1_3[[#This Row],[Admission_Date]] -> 44591 | P32: 6417.96 | Q32: =SUMPRODUCT(($L$2:$L$5000=L32)*($O$2:$O$5000>P32))+1 -> 107 | R32: Senior | S32: 26.383673 | T32: Overweight | U32: =INDEX(Table2[Doctor_Name],MATCH(Table1_3[[#This Row],[Department]],Table2[Department],0)) -> Dr. Vikram Wang
A33: PT-1032 | B33: Aadhya Lopez | C33: 68 | D33: Other | E33: Jaipur | F33: B- | G33: Unknown | H33: 162.2 | I33: 104 | J33: Yes | K33: Yes | L33: Cardiology | M33: 44795 | N33: =Table1_3[[#This Row],[Admission_Date]] -> 44795 | O33: =Table1_3[[#This Row],[Admission_Date]] -> 44795 | P33: 47232.44 | Q33: =SUMPRODUCT(($L$2:$L$5000=L33)*($O$2:$O$5000>P33))+1 -> 1 | R33: Senior | S33: 39.530439 | T33: Obese | U33: =INDEX(Table2[Doctor_Name],MATCH(Table1_3[[#This Row],[Department]],Table2[Department],0)) -> Dr. Vikram Wang
A34: PT-1032 | B34: Omar Rodriguez | C34: 55 | D34: Female | E34: Pune | F34: O+ | G34: Unknown | H34: 150 | I34: 40.8 | J34: No | K34: Yes | L34: Psychiatry | M34: 44804 | N34: =Table1_3[[#This Row],[Admission_Date]] -> 44804 | O34: =Table1_3[[#This Row],[Admission_Date]] -> 44804 | P34: 25241.72 | Q34: =SUMPRODUCT(($L$2:$L$5000=L34)*($O$2:$O$5000>P34))+1 -> 34 | R34: Adult | S34: 18.133333 | T34: Underweight | U34: =INDEX(Table2[Doctor_Name],MATCH(Table1_3[[#This Row],[Department]],Table2[Department],0)) -> Dr. Vikram Torres
A35: PT-1033 | B35: Aarav Sanchez | C35: 44 | D35: Male | E35: Delhi | F35: A+ | G35: Diabetes Type 2 | H35: 168.4 | I35: 92 | J35: Yes | K35: Yes | L35: Endocrinology | M35: 44819 | N35: =Table1_3[[#This Row],[Admission_Date]] -> 44819 | O35: =Table1_3[[#This Row],[Admission_Date]] -> 44819 | P35: 49698.95 | Q35: =SUMPRODUCT(($L$2:$L$5000=L35)*($O$2:$O$5000>P35))+1 -> 1 | R35: Adult | S35: 32.441704 | T35: Obese | U35: =INDEX(Table2[Doctor_Name],MATCH(Table1_3[[#This Row],[Department]],Table2[Department],0)) -> Dr. Rahul Nair
A36: PT-1034 | B36: Noor Jones | C36: 57 | D36: Male | E36: Toronto | F36: Unknown | G36: Arthritis | H36: 152 | I36: 59 | J36: Yes | K36: Unknown | L36: Cardiology | M36: 44518 | N36: =Table1_3[[#This Row],[Admission_Date]] -> 44518 | O36: =Table1_3[[#This Row],[Admission_Date]] -> 44518 | P36: 9103.77 | Q36: =SUMPRODUCT(($L$2:$L$5000=L36)*($O$2:$O$5000>P36))+1 -> 107 | R36: Adult | S36: 25.536704 | T36: Overweight | U36: =INDEX(Table2[Doctor_Name],MATCH(Table1_3[[#This Row],[Department]],Table2[Department],0)) -> Dr. Vikram Wang
A37: PT-1035 | B37: Layla Lopez | C37: 91 | D37: Male | E37: Chennai | F37: Ab- | G37: Asthma | H37: 187.9 | I37: 89 | J37: Yes | K37: Yes | L37: Cardiology | M37: 44319 | N37: =Table1_3[[#This Row],[Admission_Date]] -> 44319 | O37: =Table1_3[[#This Row],[Admission_Date]] -> 44319 | P37: 39735.11 | Q37: =SUMPRODUCT(($L$2:$L$5000=L37)*($O$2:$O$5000>P37))+1 -> 107 | R37: Senior | S37: 25.207887 | T37: Overweight | U37: =INDEX(Table2[Doctor_Name],MATCH(Table1_3[[#This Row],[Department]],Table2[Department],0)) -> Dr. Vikram Wang
... A41: PT-1039 | B41: Li Nair | C41: 31 | D41: Female | E41: Kolkata | F41: B+ | G41: Depression | H41: 178.8 | I41: 60 | J41: No | K41: No | L41: Dermatology | M41: 44541 | N41: =Table1_3[[#This Row],[Admission_Date]] -> 44541 | O41: =Table1_3[[#This Row],[Admission_Date]] -> 44541 | P41: 46666.33 | Q41: =SUMPRODUCT(($L$2:$L$5000=L41)*($O$2:$O$5000>P41))+1 -> 1 | R41: Adult | S41: 18.767923 | T41: Normal | U41: =INDEX(Table2[Doctor_Name],MATCH(Table1_3[[#This Row],[Department]],Table2[Department],0)) -> Dr. Neha Liu
A42: PT-1040 | B42: Lopez Wei | C42: 50 | D42: Female | E42: Sydney | F42: O+ | G42: Diabetes Type 2 | H42: Invalid | I42: 110.9 | J42: Yes | K42: Yes | L42: Gastroenterology | M42: 44660 | N42: =Table1_3[[#This Row],[Admission_Date]] -> 44660 | O42: =Table1_3[[#This Row],[Admission_Date]] -> 44660 | P42: 29206.21 | Q42: =SUMPRODUCT(($L$2:$L$5000=L42)*($O$2:$O$5000>P42))+1 -> 42 | R42: Adult | S42: Unknown | T42: Unknown | U42: =INDEX(Table2[Doctor_Name],MATCH(Table1_3[[#This Row],[Department]],Table2[Department],0)) -> Dr. Sunita Sanchez
A43: PT-1041 | B43: Wei Zhang | C43: 49 | D43: Female | E43: Mumbai | F43: Ab+ | G43: Bronchitis | H43: 155 | I43: Invalid | J43: No | K43: Unknown | L43: Nephrology | M43: 44977 | N43: =Table1_3[[#This Row],[Admission_Date]] -> 44977 | O43: =Table1_3[[#This Row],[Admission_Date]] -> 44977 | P43: 49426.49 | Q43: =SUMPRODUCT(($L$2:$L$5000=L43)*($O$2:$O$5000>P43))+1 -> 1 | R43: Adult | S43: Unknown | T43: Unknown | U43: =INDEX(Table2[Doctor_Name],MATCH(Table1_3[[#This Row],[Department]],Table2[Department],0)) -> Dr. Meera Torres
A44: PT-1042 | B44: Aditya Iyer | C44: 13 | D44: Female | E44: Chicago | F44: B- | G44: Chronic Kidney Disease | H44: 155.5 | I44: 99 | J44: No | K44: No | L44: Endocrinology | M44: 44739 | N44: =Table1_3[[#This Row],[Admission_Date]] -> 44739 | O44: =Table1_3[[#This Row],[Admission_Date]] -> 44739 | P44: 31351.34 | Q44: =SUMPRODUCT(($L$2:$L$5000=L44)*($O$2:$O$5000>P44))+1 -> 45 | R44: Child | S44: 40.942505 | T44: Obese | U44: =INDEX(Table2[Doctor_Name],MATCH(Table1_3[[#This Row],[Department]],Table2[Department],0)) -> Dr. Rahul Nair
A45: PT-1043 | B45: Ana Rodriguez | C45: 92 | D45: Male | E45: Los Angeles | F45: A- | G45: Thyroid Disorder | H45: 146.6 | I45: 107.2 | J45: No | K45: Unknown | L45: Gastroenterology | M45: 44402 | N45: =Table1_3[[#This Row],[Admission_Date]] -> 44402 | O45: =Table1_3[[#This Row],[Admission_Date]] -> 44402 | P45: 8735.06 | Q45: =SUMPRODUCT(($L$2:$L$5000=L45)*($O$2:$O$5000>P45))+1 -> 42 | R45: Senior | S45: 49.880046 | T45: Obese | U45: =INDEX(Table2[Doctor_Name],MATCH(Table1_3[[#This Row],[Department]],Table2[Department],0)) -> Dr. Sunita Sanchez
A46: PT-1044 | B46: Vihaan Wilson | C46: 32 | D46: Other | E46: New York | F46: O- | G46: Obesity | H46: 147.3 | I46: 62 | J46: No | K46: No | L46: Dermatology | M46: 44687 | N46: =Table1_3[[#This Row],[Admission_Date]] -> 44687 | O46: =Table1_3[[#This Row],[Admission_Date]] -> 44687 | P46: 0 | Q46: =SUMPRODUCT(($L$2:$L$5000=L46)*($O$2:$O$5000>P46))+1 -> 35 | R46: Adult | S46: 28.574997 | T46: Overweight | U46: =INDEX(Table2[Doctor_Name],MATCH(Table1_3[[#This Row],[Department]],Table2[Department],0)) -> Dr. Neha Liu
...

Sheet Doctor_Reference
A1: Doctor_ID | B1: Doctor_Name | C1: Department | D1: Years_Experience | E1: Consultation_Fee
A2: DOC-101 | B2: Dr. Arvind Chen | C2: Pediatrics | D2: 30
A3: DOC-102 | B3: Dr. Sunita Zhang | C3: ENT | D3: NA | E3: 2989
A4: DOC-103 | B4: Dr. Arvind Wilson | C4: General Medicine
A5: DOC-104 | B5: Dr. Vikram Torres | C5: Psychiatry | D5: 8
A6: DOC-105 | B6: Dr. Anita Sanchez | C6: Orthopedics | E6: -100
A7: DOC-106 | B7: Dr. Rahul Khan | C7: orthopedics | D7: NA | E7: Free
A8: DOC-107 | B8: Dr. Neha Liu | C8: Dermatology | D8: -2 | E8: -100
A9: DOC-108 | B9: Dr. Kavita Suzuki | C9: Pediatrics | D9: -2 | E9: -100
A10: DOC-109 | B10: Dr. Suresh Johnson | C10: Oncology | D10: 19 | E10: Free
A11: DOC-110 | B11: Dr. Arvind Ibrahim | C11: Dermatology | D11: 12 | E11: -100
A12: DOC-111 | B12: Dr. Vikram Khan | C12: Neurology | E12: 674
A13: DOC-112 | B13: Dr. Sunita Sanchez | C13: Gastroenterology | D13: 27
A14: DOC-113 | B14: Dr. Suresh Sanchez | C14: Dermatology | D14: 31 | E14: 2870
A15: DOC-114 | B15: Dr. Meera Torres | C15: Nephrology
A16: DOC-115 | B16: Dr. Pooja Liu | C16: Gastroenterology
A17: DOC-116 | B17: Dr. Neha Iyer | C17: Orthopedics | D17: 5 | E17: -100
A18: DOC-117 | B18: Dr. Pooja Garcia | C18: Dermatology | E18: -100
A19: DOC-118 | B19: Dr. Rahul Nair | C19: Endocrinology | E19: 961
A20: DOC-119 | B20: Dr. Rajesh Gupta | C20: Dermatology | D20: NA | E20: 2628
A21: DOC-120 | B21: Dr. Arvind Khan | C21: Orthopedics | D21: 35 | E21: 2233
A22: DOC-121 | B22: Dr. Pooja Lopez | C22: Psychiatry | D22: -2 | E22: 2491
A23: DOC-122 | B23: Dr. Neha Suzuki | C23: Gastroenterology | D23: NA | E23: 1457
A24: DOC-123 | B24: Dr. Anita Mehta | C24: Psychiatry | D24: 17 | E24: Free
A25: DOC-124 | B25: Dr. Vikram Wang | C25: cardiology | D25: NA | E25: 867
A26: DOC-125 | B26: Dr. Neha Kumar | C26: Pediatrics | E26: Free

Sheet Lab_Results
A1: Test_ID | B1: Patient_ID | C1: Test_Name | D1: Test_Date | E1: Result_Value | F1: Unit | G1: Normal_Range | H1: Status | I1: Orpahn_check
A2: LAB-2001 | B2: PT-1539 | C2: Hemoglobin | D2: 2022/07/18 | E2: 197.9 | F2: g/dL | G2: 12-17 | H2: Normal | I2: =IF(COUNTIF(Old_Patient_Records!$A$2:$A$549,Table4[[#This Row],[Patient_ID]])=0,"Orphan","Valid") -> Valid
A3: LAB-2002 | B3: PT-1282 | C3: Cholesterol | D3: 13.01.2023 | E3: 11.4 | F3: mg/dL | G3: 125-200 | H3: HIGH | I3: =IF(COUNTIF(Old_Patient_Records!$A$2:$A$549,Table4[[#This Row],[Patient_ID]])=0,"Orphan","Valid") -> Valid
A4: LAB-2003 | B4: PT-1335 | C4: Hemoglobin | D4: 20.06.2023 | E4: 144.1 | F4: g/dL | G4: 12-17 | H4: HIGH | I4: =IF(COUNTIF(Old_Patient_Records!$A$2:$A$549,Table4[[#This Row],[Patient_ID]])=0,"Orphan","Valid") -> Valid
A5: LAB-2004 | B5: PT-1111 | C5: Cholesterol | D5: 02-26-2023 | E5: 40.9 | F5: mg/dL | G5: 125-200 | H5: normal | I5: =IF(COUNTIF(Old_Patient_Records!$A$2:$A$549,Table4[[#This Row],[Patient_ID]])=0,"Orphan","Valid") -> Valid
A6: LAB-2005 | B6: PT-1095 | C6: Blood Glucose | D6: 16.01.2023 | F6: mg/dL | G6: 70-110 | H6: Pending | I6: =IF(COUNTIF(Old_Patient_Records!$A$2:$A$549,Table4[[#This Row],[Patient_ID]])=0,"Orphan","Valid") -> Valid
A7: LAB-2006 | B7: PT-1086 | C7: WBC Count | D7: 12-15-2021 | E7: 104.4 | F7: cells/uL | G7: 4500-11000 | H7: Low | I7: =IF(COUNTIF(Old_Patient_Records!$A$2:$A$549,Table4[[#This Row],[Patient_ID]])=0,"Orphan","Valid") -> Valid
A8: LAB-2007 | B8: PT-1235 | C8: BMI | D8: 21.09.2023 | E8: 133.2 | F8: kg/m2 | G8: 18.5-25 | H8: Low | I8: =IF(COUNTIF(Old_Patient_Records!$A$2:$A$549,Table4[[#This Row],[Patient_ID]])=0,"Orphan","Valid") -> Valid
A9: LAB-2008 | B9: PT-1006 | C9: BMI | D9: 05-13-2021 | F9: kg/m2 | G9: 18.5-25 | H9: normal | I9: =IF(COUNTIF(Old_Patient_Records!$A$2:$A$549,Table4[[#This Row],[Patient_ID]])=0,"Orphan","Valid") -> Valid
A10: LAB-2009 | B10: PT-1228 | C10: Hemoglobin | D10: 02.09.2021 | E10: 73.2 | F10: g/dL | G10: 12-17 | H10: normal | I10: =IF(COUNTIF(Old_Patient_Records!$A$2:$A$549,Table4[[#This Row],[Patient_ID]])=0,"Orphan","Valid") -> Valid
A11: LAB-2010 | B11: PT-1411 | C11: Hemoglobin | D11: 10/12/2023 | E11: 210.8 | F11: g/dL | G11: 12-17 | H11: normal | I11: =IF(COUNTIF(Old_Patient_Records!$A$2:$A$549,Table4[[#This Row],[Patient_ID]])=0,"Orphan","Valid") -> Valid
A12: LAB-2011 | B12: PT-1456 | C12: Hemoglobin | D12: 2023-11-06 | E12: 158.5 | F12: g/dL | G12: 12-17 | H12: HIGH | I12: =IF(COUNTIF(Old_Patient_Records!$A$2:$A$549,Table4[[#This Row],[Patient_ID]])=0,"Orphan","Valid") -> Valid
A13: LAB-2012 | B13: PT-1070 | C13: BMI | D13: 07/12/2023 | E13: 242.8 | F13: kg/m2 | G13: 18.5-25 | H13: normal | I13: =IF(COUNTIF(Old_Patient_Records!$A$2:$A$549,Table4[[#This Row],[Patient_ID]])=0,"Orphan","Valid") -> Valid
A14: LAB-2013 | B14: PT-1489 | C14: Hemoglobin | D14: 17/05/2022 | E14: 174 | F14: g/dL | G14: 12-17 | I14: =IF(COUNTIF(Old_Patient_Records!$A$2:$A$549,Table4[[#This Row],[Patient_ID]])=0,"Orphan","Valid") -> Valid
A15: LAB-2014 | B15: PT-1470 | C15: Cholesterol | D15: 25.01.2022 | E15: 140.2 | F15: mg/dL | G15: 125-200 | H15: High | I15: =IF(COUNTIF(Old_Patient_Records!$A$2:$A$549,Table4[[#This Row],[Patient_ID]])=0,"Orphan","Valid") -> Valid
A16: LAB-2015 | B16: PT-1284 | C16: Cholesterol | D16: 05-Sep-2023 | E16: 55.9 | F16: mg/dL | G16: 125-200 | H16: High | I16: =IF(COUNTIF(Old_Patient_Records!$A$2:$A$549,Table4[[#This Row],[Patient_ID]])=0,"Orphan","Valid") -> Valid
A17: LAB-2016 | B17: PT-1510 | C17: BMI | D17: 07-Feb-2022 | E17: 83.1 | F17: kg/m2 | G17: 18.5-25 | H17: High | I17: =IF(COUNTIF(Old_Patient_Records!$A$2:$A$549,Table4[[#This Row],[Patient_ID]])=0,"Orphan","Valid") -> Valid
A18: LAB-2017 | B18: PT-1222 | C18: Blood Pressure | D18: 09-25-2023 | E18: 29.5 | F18: mmHg | G18: 90/60-120/80 | H18: Normal | I18: =IF(COUNTIF(Old_Patient_Records!$A$2:$A$549,Table4[[#This Row],[Patient_ID]])=0,"Orphan","Valid") -> Valid
A19: LAB-2018 | B19: PT-1220 | C19: BMI | D19: 2022/02/03 | E19: 181.4 | F19: kg/m2 | G19: 18.5-25 | I19: =IF(COUNTIF(Old_Patient_Records!$A$2:$A$549,Table4[[#This Row],[Patient_ID]])=0,"Orphan","Valid") -> Valid
A20: LAB-2019 | B20: PT-1526 | C20: Blood Glucose | D20: 12-28-2021 | E20: 152.3 | F20: mg/dL | G20: 70-110 | H20: Pending | I20: =IF(COUNTIF(Old_Patient_Records!$A$2:$A$549,Table4[[#This Row],[Patient_ID]])=0,"Orphan","Valid") -> Valid
A21: LAB-2020 | B21: PT-1326 | C21: Blood Pressure | D21: 11-30-2022 | E21: 69.7 | F21: mmHg | G21: 90/60-120/80 | H21: Pending | I21: =IF(COUNTIF(Old_Patient_Records!$A$2:$A$549,Table4[[#This Row],[Patient_ID]])=0,"Orphan","Valid") -> Valid
A22: LAB-2021 | B22: PT-1251 | C22: BMI | D22: 09-Jan-2022 | E22: 32.3 | F22: kg/m2 | G22: 18.5-25 | H22: Normal | I22: =IF(COUNTIF(Old_Patient_Records!$A$2:$A$549,Table4[[#This Row],[Patient_ID]])=0,"Orphan","Valid") -> Valid
A23: LAB-2022 | B23: PT-1178 | C23: Hemoglobin | D23: 15-May-2021 | E23: 120.3 | F23: g/dL | G23: 12-17 | H23: HIGH | I23: =IF(COUNTIF(Old_Patient_Records!$A$2:$A$549,Table4[[#This Row],[Patient_ID]])=0,"Orphan","Valid") -> Valid
A24: LAB-2023 | B24: PT-1226 | C24: Blood Glucose | D24: 10/01/2022 | E24: 88.9 | F24: mg/dL | G24: 70-110 | H24: High | I24: =IF(COUNTIF(Old_Patient_Records!$A$2:$A$549,Table4[[#This Row],[Patient_ID]])=0,"Orphan","Valid") -> Valid
A25: LAB-2024 | B25: PT-1089 | C25: Cholesterol | D25: 2023-08-25 | E25: 79.8 | F25: mg/dL | G25: 125-200 | H25: HIGH | I25: =IF(COUNTIF(Old_Patient_Records!$A$2:$A$549,Table4[[#This Row],[Patient_ID]])=0,"Orphan","Valid") -> Valid
A26: LAB-2025 | B26: PT-1180 | C26: BMI | D26: 23/03/2023 | E26: 84.3 | F26: kg/m2 | G26: 18.5-25 | H26: Low | I26: =IF(COUNTIF(Old_Patient_Records!$A$2:$A$549,Table4[[#This Row],[Patient_ID]])=0,"Orphan","Valid") -> Valid
A27: LAB-2026 | B27: PT-1306 | C27: BMI | D27: 04.05.2023 | E27: 239.4 | F27: kg/m2 | G27: 18.5-25 | H27: HIGH | I27: =IF(COUNTIF(Old_Patient_Records!$A$2:$A$549,Table4[[#This Row],[Patient_ID]])=0,"Orphan","Valid") -> Valid
A28: LAB-2027 | B28: PT-1349 | C28: Cholesterol | D28: 30/01/2023 | E28: 233.9 | F28: mg/dL | G28: 125-200 | H28: HIGH | I28: =IF(COUNTIF(Old_Patient_Records!$A$2:$A$549,Table4[[#This Row],[Patient_ID]])=0,"Orphan","Valid") -> Valid
A29: LAB-2028 | B29: PT-1537 | C29: Hemoglobin | D29: 17-Mar-2023 | E29: 115.2 | F29: g/dL | G29: 12-17 | H29: Normal | I29: =IF(COUNTIF(Old_Patient_Records!$A$2:$A$549,Table4[[#This Row],[Patient_ID]])=0,"Orphan","Valid") -> Valid
A30: LAB-2029 | B30: PT-1359 | C30: Blood Pressure | D30: 07-25-2023 | E30: 91.6 | F30: mmHg | G30: 90/60-120/80 | H30: Normal | I30: =IF(COUNTIF(Old_Patient_Records!$A$2:$A$549,Table4[[#This Row],[Patient_ID]])=0,"Orphan","Valid") -> Valid
A31: LAB-2030 | B31: PT-1071 | C31: WBC Count | D31: 22-Oct-2022 | E31: 77.2 | F31: cells/uL | G31: 4500-11000 | H31: Critical | I31: =IF(COUNTIF(Old_Patient_Records!$A$2:$A$549,Table4[[#This Row],[Patient_ID]])=0,"Orphan","Valid") -> Valid
... A34: LAB-2033 | B34: PT-1393 | C34: WBC Count | D34: 2023-02-08 | E34: 66.2 | F34: cells/uL | G34: 4500-11000 | H34: High | I34: =IF(COUNTIF(Old_Patient_Records!$A$2:$A$549,Table4[[#This Row],[Patient_ID]])=0,"Orphan","Valid") -> Valid
A35: LAB-2034 | B35: PT-1168 | C35: Blood Glucose | D35: 2022-08-06 | E35: 136.8 | F35: mg/dL | G35: 70-110 | I35: =IF(COUNTIF(Old_Patient_Records!$A$2:$A$549,Table4[[#This Row],[Patient_ID]])=0,"Orphan","Valid") -> Valid
A36: LAB-2035 | B36: PT-1365 | C36: Cholesterol | D36: 28/04/2023 | E36: 84.5 | F36: mg/dL | G36: 125-200 | H36: Low | I36: =IF(COUNTIF(Old_Patient_Records!$A$2:$A$549,Table4[[#This Row],[Patient_ID]])=0,"Orphan","Valid") -> Valid
A37: LAB-2036 | B37: PT-1255 | C37: BMI | D37: 2022/11/03 | E37: 142.6 | F37: kg/m2 | G37: 18.5-25 | H37: Pending | I37: =IF(COUNTIF(Old_Patient_Records!$A$2:$A$549,Table4[[#This Row],[Patient_ID]])=0,"Orphan","Valid") -> Valid
A38: LAB-2037 | B38: PT-1341 | C38: WBC Count | D38: 2021-10-15 | E38: 205.2 | F38: cells/uL | G38: 4500-11000 | H38: abnormal | I38: =IF(COUNTIF(Old_Patient_Records!$A$2:$A$549,Table4[[#This Row],[Patient_ID]])=0,"Orphan","Valid") -> Valid
A39: LAB-2038 | B39: PT-1532 | C39: Hemoglobin | D39: 20-Oct-2022 | E39: 188.1 | F39: g/dL | G39: 12-17 | H39: normal | I39: =IF(COUNTIF(Old_Patient_Records!$A$2:$A$549,Table4[[#This Row],[Patient_ID]])=0,"Orphan","Valid") -> Valid
A40: LAB-2039 | B40: PT-1078 | C40: Blood Pressure | D40: 2022/06/07 | E40: 171 | F40: mmHg | G40: 90/60-120/80 | H40: Normal | I40: =IF(COUNTIF(Old_Patient_Records!$A$2:$A$549,Table4[[#This Row],[Patient_ID]])=0,"Orphan","Valid") -> Valid
A41: LAB-2040 | B41: PT-1107 | C41: Cholesterol | D41: 2021/04/09 | E41: 109.7 | F41: mg/dL | G41: 125-200 | H41: Normal | I41: =IF(COUNTIF(Old_Patient_Records!$A$2:$A$549,Table4[[#This Row],[Patient_ID]])=0,"Orphan","Valid") -> Valid
A42: LAB-2041 | B42: PT-1187 | C42: BMI | D42: 2022/11/01 | E42: 248.9 | F42: kg/m2 | G42: 18.5-25 | I42: =IF(COUNTIF(Old_Patient_Records!$A$2:$A$549,Table4[[#This Row],[Patient_ID]])=0,"Orphan","Valid") -> Valid
...

Sheet Pivot_Tables
A2: Diagnosis | B2: Average of Bill_Amount | D2: Count of Gender | E2: Gender | O2: Age Group | P2: Count of Patient_ID2 | Q2: Percent of Patient_ID
A3: Arthritis | B3: 29863.701 | D3: Department | E3: Female | F3: Male | G3: Other | H3: Grand Total | O3: Adult | P3: 189 | Q3: 0.35
A4: Thyroid Disorder | B4: 28203.213 | D4: Cardiology | E4: 43 | F4: 49 | G4: 14 | H4: 106 | O4: Child | P4: 107 | Q4: 0.19814815
A5: Heart Disease | B5: 27518.682 | D5: Dermatology | E5: 13 | F5: 17 | G5: 4 | H5: 34 | O5: Senior | P5: 181 | Q5: 0.33518519
A6: Allergy | B6: 26509.152 | D6: Endocrinology | E6: 19 | F6: 20 | G6: 5 | H6: 44 | O6: Unknown | P6: 20 | Q6: 0.037037037
A7: Anxiety | B7: 26317.88 | D7: Ent | E7: 13 | F7: 10 | G7: 6 | H7: 29 | O7: Young Adult | P7: 43 | Q7: 0.07962963
A8: Covid19 | B8: 25305.122 | D8: Gastroenterology | E8: 20 | F8: 15 | G8: 6 | H8: 41 | O8: Grand Total | P8: 540 | Q8: 1
A9: Asthma | B9: 25286.913 | D9: General Medicine | E9: 13 | F9: 15 | G9: 9 | H9: 37
A10: Pneumonia | B10: 24962.895 | D10: Nephrology | E10: 14 | F10: 14 | G10: 6 | H10: 34 | O10: TOP5 COSTLIEST PATIENTS
A11: Tuberculosis | B11: 24791.926 | D11: Neurology | E11: 16 | F11: 15 | G11: 3 | H11: 34 | O11: Row Labels | P11: Sum of Bill_Amount
A12: Migraine | B12: 24616.86 | D12: Oncology | E12: 15 | F12: 15 | H12: 30 | O12: Valentina Iyer | P12: 97966.8
A13: Grand Total | B13: 26064.251 | D13: Orthopedics | E13: 38 | F13: 35 | G13: 9 | H13: 82 | O13: Robert Liu | P13: 89109.57
D14: Pediatrics | E14: 15 | F14: 17 | G14: 4 | H14: 36 | O14: Valentina Rodriguez | P14: 85288.55
D15: Psychiatry | E15: 12 | F15: 16 | G15: 5 | H15: 33 | O15: Hiroshi Reddy | P15: 84009.88
D16: Grand Total | E16: 231 | F16: 238 | G16: 71 | H16: 540 | O16: Juan Sanchez | P16: 83305.57
O17: Grand Total | P17: 439680.37
B19: Department-wise Monthly Billing Heatmap
A20: Department | B20: Jan | C20: Feb | D20: Mar | E20: Apr | F20: May | G20: Jun | H20: Jul | I20: Aug | J20: Sep | K20: Oct | L20: Nov | M20: Dec | O20: Sum of Bill_Amount | P20: Year
A21: Cardiology | B21: 348481.29 | C21: 231805.6 | D21: 304994.69 | E21: 326603.58 | F21: 343578.78 | G21: 97152.64 | H21: 343264.1 | I21: 164673.18 | J21: 106887.89 | K21: 170183.72 | L21: 55078.45 | M21: 237397.34 | P21: 2021 | Q21: 2022 | R21: 2023 | S21: Grand Total
A22: Dermatology | B22: 7522.8 | C22: 184802.08 | D22: 62989.46 | E22: 59743.28 | F22: 82205.1 | G22: 88463.46 | I22: 57539.61 | J22: 55425.3 | K22: 19885.72 | L22: 107598.39 | M22: 82941.84 | O22: City
A23: Endocrinology | B23: 181281.67 | C23: 51576.87 | D23: 43171.49 | E23: 142672.81 | F23: 16429.2 | G23: 86064.99 | H23: 35724.67 | I23: 167157.35 | J23: 143150.97 | K23: 29724.21 | L23: 47698.24 | M23: 80087.09 | O23: Ahmedabad | P23: 248928.03 | Q23: 296067.32 | R23: 221841.62 | S23: 766836.97
A24: Ent | B24: 78290.25 | C24: 123079.9 | D24: 4321.48 | E24: 11993.04 | F24: 30725.23 | G24: 15145.68 | H24: 55719.96 | I24: 76148.16 | J24: 63323.84 | K24: 69807.04 | L24: 59554.96 | M24: 60411.66 | O24: Bengaluru | P24: 556584.15 | Q24: 459203.52 | R24: 520636 | S24: 1536423.7
A25: Gastroenterology | B25: 62987.6 | C25: 121487.33 | D25: 92403.78 | E25: 81128.4 | F25: 89924.48 | G25: 20625.49 | H25: 105545.84 | I25: 107867.2 | J25: 50895.96 | K25: 1061.85 | L25: 97886.08 | M25: 45256.48 | O25: Chennai | P25: 444337.32 | Q25: 315562.89 | R25: 508550.45 | S25: 1268450.7
A26: General Medicine | B26: 105519.22 | C26: 35510.31 | D26: 20931.83 | E26: 90359.47 | F26: 158784.13 | H26: 43252.29 | I26: 102432.18 | J26: 47809.72 | K26: 76545.77 | L26: 44662.87 | M26: 73778.95 | O26: Chicago | P26: 168365.92 | Q26: 118539.9 | R26: 144543.16 | S26: 431448.98
A27: Nephrology | B27: 26510.16 | C27: 119839.16 | D27: 188735.24 | E27: 122216.23 | F27: 18791.59 | G27: 127777.51 | H27: 66155.45 | I27: 32459.78 | J27: 82120.24 | K27: 108646.37 | L27: 118228.73 | M27: 14847.88 | O27: Delhi | P27: 430625.31 | Q27: 353052.52 | R27: 507386.18 | S27: 1291064
A28: Neurology | B28: 110029.38 | C28: 97892.74 | D28: 75269.19 | E28: 88231.46 | F28: 108340.54 | G28: 119922.19 | I28: 127665.36 | J28: 49154.97 | L28: 4280.78 | M28: 26490.25 | O28: Houston | P28: 269080.27 | Q28: 182328.81 | R28: 186734.94 | S28: 638144.02
A29: Oncology | B29: 79296.82 | C29: 79687.05 | D29: 53790.49 | E29: 29732.58 | F29: 26010.78 | G29: 140449.63 | H29: 86645.13 | I29: 25106.56 | J29: 43668.91 | K29: 61205.6 | L29: 89748.83 | M29: 33727.47 | O29: Hyderabad | P29: 341992.61 | Q29: 329343.56 | R29: 284463.72 | S29: 955799.89
A30: Orthopedics | B30: 207609.3 | C30: 148420.28 | D30: 129087.04 | E30: 154494.38 | F30: 100604.4 | G30: 130102.24 | H30: 190270.94 | I30: 311641.22 | J30: 60725.66 | K30: 137697.64 | L30: 101888.65 | M30: 204149.28 | O30: Jaipur | P30: 90775.26 | Q30: 381527.74 | R30: 101766.38 | S30: 574069.38
A31: Pediatrics | B31: 85482.39 | C31: 77286.24 | D31: 126256.85 | E31: 40680.29 | F31: 135933.74 | G31: 33482.67 | H31: 153104.87 | I31: 76679.05 | J31: 48732.76 | K31: 18849.89 | L31: 4007.55 | M31: 5651.76 | O31: Kolkata | P31: 239999.89 | Q31: 157525.81 | R31: 98004.03 | S31: 495529.73
A32: Psychiatry | B32: 97477.61 | C32: 66133.72 | E32: 44697.98 | F32: 36677.15 | G32: 178997.8 | H32: 43124.4 | I32: 69383.59 | J32: 143460.36 | K32: 65239.25 | L32: 94083.35 | M32: 29044.13 | O32: London | P32: 222910.2 | Q32: 113135.44 | R32: 110130.16 | S32: 446175.8
O33: Los Angeles | P33: 96411.05 | Q33: 17514.28 | R33: 130209.15 | S33: 244134.48
O34: Mumbai | P34: 574019.56 | Q34: 465587.88 | R34: 664351.42 | S34: 1703958.9
O35: New York | P35: 100971.09 | Q35: 310062.06 | R35: 140186.94 | S35: 551220.09
O36: Pune | P36: 329284.01 | Q36: 366201.76 | R36: 568323.57 | S36: 1263809.3
O37: Sydney | P37: 213319.57 | Q37: 42009.09 | R37: 143944.31 | S37: 399272.97
O38: Toronto | P38: 134577.07 | Q38: 111635.46 | R38: 210418.39 | S38: 456630.92
O39: Grand Total | P39: 4462181.3 | Q39: 4019298 | R39: 4541490.4 | S39: 13022970

Sheet Dashboard
E1: HOSPITAL ANALYTICS RECORD
C2: TOTAL PATIENTS | F2: AVERAGE AGE | J2: TOTAL BILLING | M2: %INSURED
C3: =COUNTA(Table1_3[Patient_ID]) -> 540 | F3: =AVERAGE(Table1_3[Age]) -> 46.761538 | J3: 13022970 | M3: =COUNTIF(Old_Patient_Records!$K$2:$K$549,"Yes")/COUNTA(Old_Patient_Records!$A$2:$A$549) -> 0.14233577
L4: Top 5 Costliest Patients
L5: PATIENTS NAME | M5: SUM OF BILL
L6: Hiroshi Reddy | M6: 84009.88
L7: Juan Sanchez | M7: 83305.57
L8: Robert Liu | M8: 89109.57
L9: Valentina Iyer | M9: 97966.8
L10: Valentina Rodriguez | M10: 85288.55
